<?xml version="1.0"?>
<robot name="drone">

  <!-- Materials -->
  <material name="grey">
    <color rgba="0.6 0.6 0.6 1"/>
  </material>
  
  <material name="black">
    <color rgba="0.1 0.1 0.1 1"/>
  </material>
  
  <material name="blue">
    <color rgba="0.1 0.1 0.8 1"/>
  </material>

  <!-- Base link (drone body) -->
  <link name="base_link">
    <inertial>
      <mass value="2.0"/>
      <origin xyz="0 0 0" rpy="0 0 0"/>
      <inertia ixx="0.0347" ixy="0.0" ixz="0.0" 
               iyy="0.0458" iyz="0.0" 
               izz="0.0977" />
    </inertial>
    
    <visual>
      <origin xyz="0 0 0" rpy="0 0 0"/>
      <geometry>
        <box size="0.3 0.3 0.1"/>
      </geometry>
      <material name="blue"/>
    </visual>
    
    <collision>
      <origin xyz="0 0 0" rpy="0 0 0"/>
      <geometry>
        <box size="0.3 0.3 0.1"/>
      </geometry>
    </collision>
  </link>

  <!-- LiDAR sensor -->
  <link name="lidar_link">
    <inertial>
      <mass value="0.1"/>
      <origin xyz="0 0 0"/>
      <inertia ixx="0.001" ixy="0.0" ixz="0.0"
               iyy="0.001" iyz="0.0" 
               izz="0.001"/>
    </inertial>
    
    <visual>
      <origin xyz="0 0 0" rpy="0 0 0"/>
      <geometry>
        <cylinder radius="0.05" length="0.04"/>
      </geometry>
      <material name="black"/>
    </visual>
    
    <collision>
      <origin xyz="0 0 0" rpy="0 0 0"/>
      <geometry>
        <cylinder radius="0.05" length="0.04"/>
      </geometry>
    </collision>
  </link>

  <joint name="lidar_joint" type="fixed">
    <parent link="base_link"/>
    <child link="lidar_link"/>
    <origin xyz="0 0 0.08" rpy="0 0 0"/>
  </joint>

  <!-- IMU sensor -->
  <link name="imu_link">
    <inertial>
      <mass value="0.01"/>
      <origin xyz="0 0 0"/>
      <inertia ixx="0.0001" ixy="0.0" ixz="0.0"
               iyy="0.0001" iyz="0.0" 
               izz="0.0001"/>
    </inertial>
    
    <visual>
      <origin xyz="0 0 0" rpy="0 0 0"/>
      <geometry>
        <box size="0.02 0.02 0.01"/>
      </geometry>
      <material name="grey"/>
    </visual>
  </link>

  <joint name="imu_joint" type="fixed">
    <parent link="base_link"/>
    <child link="imu_link"/>
    <origin xyz="0 0 0.02" rpy="0 0 0"/>
  </joint>

  <!-- Wheels for differential drive -->
  <link name="left_wheel">
    <inertial>
      <mass value="0.5"/>
      <origin xyz="0 0 0" rpy="1.5708 0 0"/>
      <inertia ixx="0.00083" ixy="0.0" ixz="0.0"
               iyy="0.00083" iyz="0.0" 
               izz="0.00125"/>
    </inertial>
    <visual>
      <origin xyz="0 0 0" rpy="1.5708 0 0"/>
      <geometry>
        <cylinder radius="0.025" length="0.02"/>
      </geometry>
      <material name="black"/>
    </visual>
    <collision>
      <origin xyz="0 0 0" rpy="1.5708 0 0"/>
      <geometry>
        <cylinder radius="0.025" length="0.02"/>
      </geometry>
    </collision>
  </link>

  <link name="right_wheel">
    <inertial>
      <mass value="0.5"/>
      <origin xyz="0 0 0" rpy="1.5708 0 0"/>
      <inertia ixx="0.00083" ixy="0.0" ixz="0.0"
               iyy="0.00083" iyz="0.0" 
               izz="0.00125"/>
    </inertial>
    <visual>
      <origin xyz="0 0 0" rpy="1.5708 0 0"/>
      <geometry>
        <cylinder radius="0.025" length="0.02"/>
      </geometry>
      <material name="black"/>
    </visual>
    <collision>
      <origin xyz="0 0 0" rpy="1.5708 0 0"/>
      <geometry>
        <cylinder radius="0.025" length="0.02"/>
      </geometry>
    </collision>
  </link>

  <joint name="left_wheel_joint" type="continuous">
    <parent link="base_link"/>
    <child link="left_wheel"/>
    <origin xyz="0 0.15 -0.03" rpy="0 0 0"/>
    <axis xyz="0 1 0"/>
  </joint>

  <joint name="right_wheel_joint" type="continuous">
    <parent link="base_link"/>
    <child link="right_wheel"/>
    <origin xyz="0 -0.15 -0.03" rpy="0 0 0"/>
    <axis xyz="0 1 0"/>
  </joint>

  <!-- Gazebo Materials -->
  <gazebo reference="base_link">
    <material>Gazebo/Blue</material>
  </gazebo>
  
  <gazebo reference="lidar_link">
    <material>Gazebo/Black</material>
  </gazebo>
  
  <gazebo reference="left_wheel">
    <material>Gazebo/Black</material>
  </gazebo>
  
  <gazebo reference="right_wheel">
    <material>Gazebo/Black</material>
  </gazebo>

  <!-- LiDAR Sensor -->
  <gazebo reference="lidar_link">
    <sensor type="ray" name="lidar_sensor">
      <pose>0 0 0 0 0 0</pose>
      <visualize>true</visualize>
      <update_rate>10</update_rate>
      <ray>
        <scan>
          <horizontal>
            <samples>360</samples>
            <resolution>1</resolution>
            <min_angle>-3.14159</min_angle>
            <max_angle>3.14159</max_angle>
          </horizontal>
        </scan>
        <range>
          <min>0.2</min>
          <max>10.0</max>
        </range>
      </ray>
      <plugin name="gazebo_ros_laser" filename="libgazebo_ros_ray_sensor.so">
        <ros>
          <remapping>~/out:=scan</remapping>
        </ros>
        <output_type>sensor_msgs/LaserScan</output_type>
      </plugin>
    </sensor>
  </gazebo>

  <!-- IMU Sensor -->
  <gazebo reference="imu_link">
    <sensor type="imu" name="imu_sensor">
      <update_rate>50</update_rate>
      <plugin name="imu_plugin" filename="libgazebo_ros_imu_sensor.so">
        <ros>
          <namespace>/</namespace>
          <remapping>imu:=/imu</remapping>
        </ros>
      </plugin>
    </sensor>
  </gazebo>

  <!-- Differential Drive Plugin -->
  <gazebo>
    <plugin name="gazebo_ros_diff_drive" filename="libgazebo_ros_diff_drive.so">
      <ros>
        <namespace>/</namespace>
        <remapping>cmd_vel:=/cmd_vel</remapping>
        <remapping>odom:=/odom</remapping>
      </ros>
      <update_rate>20.0</update_rate>
      <publish_tf>true</publish_tf>
      <publish_odom>true</publish_odom>
      <publish_odom_tf>true</publish_odom_tf>
      <publish_wheel_tf>true</publish_wheel_tf>
      <odometry_frame>odom</odometry_frame>
      <robot_base_frame>base_link</robot_base_frame>
      <wheel_separation>0.3</wheel_separation>
      <wheel_diameter>0.05</wheel_diameter>
      <max_wheel_torque>20</max_wheel_torque>
      <max_wheel_acceleration>1.0</max_wheel_acceleration>
      <left_joint>left_wheel_joint</left_joint>
      <right_joint>right_wheel_joint</right_joint>
    </plugin>
  </gazebo>

</robot>